Workbook
Name btnShowItemComment: '2월'!#REF!

Sheet 2월(집계)
A1: 발생주의 | B1: 부과기준(교통/관리비) | F1: 금액 | J1: 비중 | N1: 이슈 | O1: 당월 | R1: 저축목표 | S1: 월 560 | T1: 연 저축 목표, 4000 | U1: 6700
A2: 계정 | B2: 대분류 | C2: 소분류 | D2: 항목세부 | E2: 2월 | F2: 공동 | G2: 엉아 | H2: 아기 | J2: 공동 | K2: 엉아 | L2: 아기 | O2: 익월 | R2: 상환목표
A3: 수입 | B3: 고정 | C3: 급여 | E3: =SUM(F3:H3) -> 12216689 | F3: =SUMIFS('2월'!$I:$I,'2월'!$D:$D,C3,'2월'!$C:$C,$F$2) -> 0 | G3: =-SUMIFS('2월'!$I:$I,'2월'!$D:$D,C3,'2월'!$C:$C,$G$2) -> 6475664 | H3: =-SUMIFS('2월'!$I:$I,'2월'!$D:$D,C3,'2월'!$C:$C,$H$2) -> 5741025 | J3: =IF(ISERROR(F3/$E$9),,(F3/$E$9)) -> 0 | K3: =IF(ISERROR(G3/$E$9),,(G3/$E$9)) -> 0.34454471 | L3: =IF(ISERROR(H3/$E$9),,(H3/$E$9)) -> 0.30545744
B4: 변동 | C4: 변동수입 | E4: =SUM(E5:E7) -> 6578155 | F4: =SUM(F5:F7) -> 6578155 | G4: =SUM(G5:G7) -> 0 | H4: =SUM(H5:H7) -> 0 | J4: =IF(ISERROR(F4/$E$9),,(F4/$E$9)) -> 0.34999785 | K4: =IF(ISERROR(G4/$E$9),,(G4/$E$9)) -> 0 | L4: =IF(ISERROR(H4/$E$9),,(H4/$E$9)) -> 0
C5: 이자 | D5: 배당 | E5: =SUM(F5:H5) -> 178155 | F5: =-SUMIFS('2월'!$I:$I,'2월'!$D:$D,C5,'2월'!$C:$C,$F$2) -> 178155 | G5: =-SUMIFS('2월'!$I:$I,'2월'!$D:$D,C5,'2월'!$C:$C,$G$2) -> 0 | H5: =-SUMIFS('2월'!$I:$I,'2월'!$D:$D,C5,'2월'!$C:$C,$H$2) -> 0 | J5: =IF(ISERROR(F5/$E$9),,(F5/$E$9)) -> 0.0094789294 | K5: =IF(ISERROR(G5/$E$9),,(G5/$E$9)) -> 0 | L5: =IF(ISERROR(H5/$E$9),,(H5/$E$9)) -> 0
C6: 수입_기타 | E6: =SUM(F6:H6) -> 400000 | F6: =-SUMIFS('2월'!$I:$I,'2월'!$D:$D,C6,'2월'!$C:$C,$F$2) -> 400000 | G6: =-SUMIFS('2월'!$I:$I,'2월'!$D:$D,C6,'2월'!$C:$C,$G$2) -> 0 | H6: =-SUMIFS('2월'!$I:$I,'2월'!$D:$D,C6,'2월'!$C:$C,$H$2) -> 0 | J6: =IF(ISERROR(F6/$E$9),,(F6/$E$9)) -> 0.021282433 | K6: =IF(ISERROR(G6/$E$9),,(G6/$E$9)) -> 0 | L6: =IF(ISERROR(H6/$E$9),,(H6/$E$9)) -> 0
C7: 회수 | D7: 예적금만기/주식매도 | E7: =SUM(F7:H7) -> 6000000 | F7: =-SUMIFS('2월'!$I:$I,'2월'!$D:$D,C7,'2월'!$C:$C,$F$2) -> 6000000 | G7: =-SUMIFS('2월'!$I:$I,'2월'!$D:$D,C7,'2월'!$C:$C,$G$2) -> 0 | H7: =-SUMIFS('2월'!$I:$I,'2월'!$D:$D,C7,'2월'!$C:$C,$H$2) -> 0 | J7: =IF(ISERROR(F7/$E$9),,(F7/$E$9)) -> 0.31923649 | K7: =IF(ISERROR(G7/$E$9),,(G7/$E$9)) -> 0 | L7: =IF(ISERROR(H7/$E$9),,(H7/$E$9)) -> 0
J8: =IF(ISERROR(F8/$E$9),,(F8/$E$9)) -> 0 | K8: =IF(ISERROR(G8/$E$9),,(G8/$E$9)) -> 0 | L8: =IF(ISERROR(H8/$E$9),,(H8/$E$9)) -> 0
A9: 수입 계 | E9: =+E3+E4 -> 18794844 | F9: =+F3+F4 -> 6578155 | G9: =+G3+G4 -> 6475664 | H9: =+H3+H4 -> 5741025
J10: =IF(ISERROR(F10/$E$100),,(F10/$E$100)) -> 0 | K10: =IF(ISERROR(G10/$E$100),,(G10/$E$100)) -> 0 | L10: =IF(ISERROR(H10/$E$100),,(H10/$E$100)) -> 0
A11: 지출 | B11: 고정 | C11: 임차 | E11: =SUM(F11:H11) -> 4306930 | F11: =SUMIFS('2월'!$I:$I,'2월'!$D:$D,C11,'2월'!$C:$C,$F$2) -> 4306930 | G11: =SUMIFS('2월'!$I:$I,'2월'!$D:$D,C11,'2월'!$C:$C,$G$2) -> 0 | H11: =SUMIFS('2월'!$I:$I,'2월'!$D:$D,C11,'2월'!$C:$C,$H$2) -> 0
C12: 관리 | E12: =SUM(E13:E18) -> 377180 | F12: =SUM(F13:F18) -> 377180 | G12: =SUM(G13:G18) -> 0 | H12: =SUM(H13:H18) -> 0 | K12: =IF(ISERROR(G12/$E$100),,(G12/$E$100)) -> 0 | L12: =IF(ISERROR(H12/$E$100),,(H12/$E$100)) -> 0
C13: 관리기본 | E13: =SUM(F13:H13) -> 158600 | F13: =SUMIFS('2월'!$I:$I,'2월'!$D:$D,C13,'2월'!$C:$C,$F$2) -> 158600 | G13: =SUMIFS('2월'!$I:$I,'2월'!$D:$D,C13,'2월'!$C:$C,$G$2) -> 0 | H13: =SUMIFS('2월'!$I:$I,'2월'!$D:$D,C13,'2월'!$C:$C,$H$2) -> 0 | J13: =IF(ISERROR(F13/$E$100),,(F13/$E$100)) -> 0.020757266 | K13: =IF(ISERROR(G13/$E$100),,(G13/$E$100)) -> 0 | L13: =IF(ISERROR(H13/$E$100),,(H13/$E$100)) -> 0
C14: 수도 | E14: =SUM(F14:H14) -> 80320 | F14: =SUMIFS('2월'!$I:$I,'2월'!$D:$D,C14,'2월'!$C:$C,$F$2) -> 80320 | G14: =SUMIFS('2월'!$I:$I,'2월'!$D:$D,C14,'2월'!$C:$C,$G$2) -> 0 | H14: =SUMIFS('2월'!$I:$I,'2월'!$D:$D,C14,'2월'!$C:$C,$H$2) -> 0 | J14: =IF(ISERROR(F14/$E$100),,(F14/$E$100)) -> 0.010512129 | K14: =IF(ISERROR(G14/$E$100),,(G14/$E$100)) -> 0 | L14: =IF(ISERROR(H14/$E$100),,(H14/$E$100)) -> 0
C15: 전기 | E15: =SUM(F15:H15) -> 44760 | F15: =SUMIFS('2월'!$I:$I,'2월'!$D:$D,C15,'2월'!$C:$C,$F$2) -> 44760 | G15: =SUMIFS('2월'!$I:$I,'2월'!$D:$D,C15,'2월'!$C:$C,$G$2) -> 0 | H15: =SUMIFS('2월'!$I:$I,'2월'!$D:$D,C15,'2월'!$C:$C,$H$2) -> 0 | J15: =IF(ISERROR(F15/$E$100),,(F15/$E$100)) -> 0.0058581035 | K15: =IF(ISERROR(G15/$E$100),,(G15/$E$100)) -> 0 | L15: =IF(ISERROR(H15/$E$100),,(H15/$E$100)) -> 0
C16: 가스 | D16: 시공비 | E16: =SUM(F16:H16) -> 93500 | F16: =SUMIFS('2월'!$I:$I,'2월'!$D:$D,C16,'2월'!$C:$C,$F$2) -> 93500 | G16: =SUMIFS('2월'!$I:$I,'2월'!$D:$D,C16,'2월'!$C:$C,$G$2) -> 0 | H16: =SUMIFS('2월'!$I:$I,'2월'!$D:$D,C16,'2월'!$C:$C,$H$2) -> 0 | J16: =IF(ISERROR(F16/$E$100),,(F16/$E$100)) -> 0.012237102 | K16: =IF(ISERROR(G16/$E$100),,(G16/$E$100)) -> 0 | L16: =IF(ISERROR(H16/$E$100),,(H16/$E$100)) -> 0
C17: 수리 | E17: =SUM(F17:H17) -> 0 | F17: =SUMIFS('2월'!$I:$I,'2월'!$D:$D,C17,'2월'!$C:$C,$F$2) -> 0 | G17: =SUMIFS('2월'!$I:$I,'2월'!$D:$D,C17,'2월'!$C:$C,$G$2) -> 0 | H17: =SUMIFS('2월'!$I:$I,'2월'!$D:$D,C17,'2월'!$C:$C,$H$2) -> 0 | J17: =IF(ISERROR(F17/$E$100),,(F17/$E$100)) -> 0 | K17: =IF(ISERROR(G17/$E$100),,(G17/$E$100)) -> 0 | L17: =IF(ISERROR(H17/$E$100),,(H17/$E$100)) -> 0
C18: 관리_기타 | D18: 예치금 | E18: =SUM(F18:H18) -> 0 | F18: =SUMIFS('2월'!$I:$I,'2월'!$D:$D,C18,'2월'!$C:$C,$F$2) -> 0 | G18: =SUMIFS('2월'!$I:$I,'2월'!$D:$D,C18,'2월'!$C:$C,$G$2) -> 0 | H18: =SUMIFS('2월'!$I:$I,'2월'!$D:$D,C18,'2월'!$C:$C,$H$2) -> 0 | J18: =IF(ISERROR(F18/$E$100),,(F18/$E$100)) -> 0 | K18: =IF(ISERROR(G18/$E$100),,(G18/$E$100)) -> 0 | L18: =IF(ISERROR(H18/$E$100),,(H18/$E$100)) -> 0
J19: =IF(ISERROR(F19/$E$100),,(F19/$E$100)) -> 0 | K19: =IF(ISERROR(G19/$E$100),,(G19/$E$100)) -> 0 | L19: =IF(ISERROR(H19/$E$100),,(H19/$E$100)) -> 0
C20: 대출상환 | E20: =SUM(F20:H20) -> 0 | F20: =SUMIFS('2월'!$I:$I,'2월'!$D:$D,C20,'2월'!$C:$C,$F$2) -> 0 | G20: =SUMIFS('2월'!$I:$I,'2월'!$D:$D,C20,'2월'!$C:$C,$G$2) -> 0 | H20: =SUMIFS('2월'!$I:$I,'2월'!$D:$D,C20,'2월'!$C:$C,$H$2) -> 0 | J20: =IF(ISERROR(F20/$E$100),,(F20/$E$100)) -> 0 | K20: =IF(ISERROR(G20/$E$100),,(G20/$E$100)) -> 0 | L20: =IF(ISERROR(H20/$E$100),,(H20/$E$100)) -> 0
C21: 대출이자 | E21: =SUM(F21:H21) -> 215020 | F21: =SUMIFS('2월'!$I:$I,'2월'!$D:$D,C21,'2월'!$C:$C,$F$2) -> 215020 | G21: =SUMIFS('2월'!$I:$I,'2월'!$D:$D,C21,'2월'!$C:$C,$G$2) -> 0 | H21: =SUMIFS('2월'!$I:$I,'2월'!$D:$D,C21,'2월'!$C:$C,$H$2) -> 0 | J21: =IF(ISERROR(F21/$E$100),,(F21/$E$100)) -> 0.028141408 | K21: =IF(ISERROR(G21/$E$100),,(G21/$E$100)) -> 0 | L21: =IF(ISERROR(H21/$E$100),,(H21/$E$100)) -> 0
J22: =IF(ISERROR(F22/$E$100),,(F22/$E$100)) -> 0 | K22: =IF(ISERROR(G22/$E$100),,(G22/$E$100)) -> 0 | L22: =IF(ISERROR(H22/$E$100),,(H22/$E$100)) -> 0
C23: 저축 | E23: =SUM(E24:E26) -> 0 | F23: =SUM(F24:F26) -> 0 | G23: =SUM(G24:G26) -> 0 | H23: =SUM(H24:H26) -> 0
C24: 예금 | E24: =SUM(F24:H24) -> 0 | F24: =SUMIFS('2월'!$I:$I,'2월'!$D:$D,C24,'2월'!$C:$C,$F$2) -> 0 | G24: =SUMIFS('2월'!$I:$I,'2월'!$D:$D,C24,'2월'!$C:$C,$G$2) -> 0 | H24: =SUMIFS('2월'!$I:$I,'2월'!$D:$D,C24,'2월'!$C:$C,$H$2) -> 0 | J24: =IF(ISERROR(F24/$E$100),,(F24/$E$100)) -> 0 | K24: =IF(ISERROR(G24/$E$100),,(G24/$E$100)) -> 0 | L24: =IF(ISERROR(H24/$E$100),,(H24/$E$100)) -> 0
C25: 적금 | E25: =SUM(F25:H25) -> 0 | F25: =SUMIFS('2월'!$I:$I,'2월'!$D:$D,C25,'2월'!$C:$C,$F$2) -> 0 | G25: =SUMIFS('2월'!$I:$I,'2월'!$D:$D,C25,'2월'!$C:$C,$G$2) -> 0 | H25: =SUMIFS('2월'!$I:$I,'2월'!$D:$D,C25,'2월'!$C:$C,$H$2) -> 0 | J25: =IF(ISERROR(F25/$E$100),,(F25/$E$100)) -> 0 | K25: =IF(ISERROR(G25/$E$100),,(G25/$E$100)) -> 0 | L25: =IF(ISERROR(H25/$E$100),,(H25/$E$100)) -> 0
C26: 주택청약 | E26: =SUM(F26:H26) -> 0 | F26: =SUMIFS('2월'!$I:$I,'2월'!$D:$D,C26,'2월'!$C:$C,$F$2) -> 0 | G26: =SUMIFS('2월'!$I:$I,'2월'!$D:$D,C26,'2월'!$C:$C,$G$2) -> 0 | H26: =SUMIFS('2월'!$I:$I,'2월'!$D:$D,C26,'2월'!$C:$C,$H$2) -> 0 | J26: =IF(ISERROR(F26/$E$100),,(F26/$E$100)) -> 0 | K26: =IF(ISERROR(G26/$E$100),,(G26/$E$100)) -> 0 | L26: =IF(ISERROR(H26/$E$100),,(H26/$E$100)) -> 0
E27: =SUM(F27:H27) -> 0 | F27: =SUMIFS('2월'!$I:$I,'2월'!$D:$D,C27,'2월'!$C:$C,$F$2) -> 0 | G27: =SUMIFS('2월'!$I:$I,'2월'!$D:$D,C27,'2월'!$C:$C,$G$2) -> 0 | H27: =SUMIFS('2월'!$I:$I,'2월'!$D:$D,C27,'2월'!$C:$C,$H$2) -> 0 | J27: =IF(ISERROR(F27/$E$100),,(F27/$E$100)) -> 0 | K27: =IF(ISERROR(G27/$E$100),,(G27/$E$100)) -> 0 | L27: =IF(ISERROR(H27/$E$100),,(H27/$E$100)) -> 0
C28: 보험 | E28: =SUM(F28:H28) -> -258363 | F28: =SUMIFS('2월'!$I:$I,'2월'!$D:$D,C28,'2월'!$C:$C,$F$2) -> 0 | G28: =SUMIFS('2월'!$I:$I,'2월'!$D:$D,C28,'2월'!$C:$C,$G$2) -> 0 | H28: =SUMIFS('2월'!$I:$I,'2월'!$D:$D,C28,'2월'!$C:$C,$H$2) -> -258363 | J28: =IF(ISERROR(F28/$E$100),,(F28/$E$100)) -> 0 | K28: =IF(ISERROR(G28/$E$100),,(G28/$E$100)) -> 0 | L28: =IF(ISERROR(H28/$E$100),,(H28/$E$100)) -> -0.033814057
J29: =IF(ISERROR(F29/$E$100),,(F29/$E$100)) -> 0 | K29: =IF(ISERROR(G29/$E$100),,(G29/$E$100)) -> 0 | L29: =IF(ISERROR(H29/$E$100),,(H29/$E$100)) -> 0
C30: 통신 | E30: =SUM(E31:E32) -> 111295 | F30: =SUM(F31:F32) -> 31350 | G30: =SUM(G31:G32) -> 28220 | H30: =SUM(H31:H32) -> 51725
C31: 전화 | E31: =SUM(F31:H31) -> 79945 | F31: =SUMIFS('2월'!$I:$I,'2월'!$D:$D,C31,'2월'!$C:$C,$F$2) -> 0 | G31: =SUMIFS('2월'!$I:$I,'2월'!$D:$D,C31,'2월'!$C:$C,$G$2) -> 28220 | H31: =SUMIFS('2월'!$I:$I,'2월'!$D:$D,C31,'2월'!$C:$C,$H$2) -> 51725 | J31: =IF(ISERROR(F31/$E$100),,(F31/$E$100)) -> 0 | K31: =IF(ISERROR(G31/$E$100),,(G31/$E$100)) -> 0.0036933798 | L31: =IF(ISERROR(H31/$E$100),,(H31/$E$100)) -> 0.0067696695
C32: 인터넷 | E32: =SUM(F32:H32) -> 31350 | F32: =SUMIFS('2월'!$I:$I,'2월'!$D:$D,C32,'2월'!$C:$C,$F$2) -> 31350 | G32: =SUMIFS('2월'!$I:$I,'2월'!$D:$D,C32,'2월'!$C:$C,$G$2) -> 0 | H32: =SUMIFS('2월'!$I:$I,'2월'!$D:$D,C32,'2월'!$C:$C,$H$2) -> 0 | J32: =IF(ISERROR(F32/$E$100),,(F32/$E$100)) -> 0.0041030283 | K32: =IF(ISERROR(G32/$E$100),,(G32/$E$100)) -> 0 | L32: =IF(ISERROR(H32/$E$100),,(H32/$E$100)) -> 0
E33: =SUM(F33:H33) -> 0 | F33: =SUMIFS('2월'!$I:$I,'2월'!$D:$D,C33,'2월'!$C:$C,$F$2) -> 0 | G33: =SUMIFS('2월'!$I:$I,'2월'!$D:$D,C33,'2월'!$C:$C,$G$2) -> 0 | H33: =SUMIFS('2월'!$I:$I,'2월'!$D:$D,C33,'2월'!$C:$C,$H$2) -> 0 | J33: =IF(ISERROR(F33/$E$100),,(F33/$E$100)) -> 0 | K33: =IF(ISERROR(G33/$E$100),,(G33/$E$100)) -> 0 | L33: =IF(ISERROR(H33/$E$100),,(H33/$E$100)) -> 0
C34: 교통 | E34: =SUM(E35:E37) -> 232800 | F34: =SUM(F35:F37) -> 232800 | G34: =SUM(G35:G37) -> 0 | H34: =SUM(H35:H37) -> 0
C35: 대중교통 | D35: 버스/지하철 | E35: =SUM(F35:H35) -> 219200 | F35: =SUMIFS('2월'!$I:$I,'2월'!$D:$D,C35,'2월'!$C:$C,$F$2) -> 219200 | G35: =SUMIFS('2월'!$I:$I,'2월'!$D:$D,C35,'2월'!$C:$C,$G$2) -> 0 | H35: =SUMIFS('2월'!$I:$I,'2월'!$D:$D,C35,'2월'!$C:$C,$H$2) -> 0 | J35: =IF(ISERROR(F35/$E$100),,(F35/$E$100)) -> 0.028688478 | K35: =IF(ISERROR(G35/$E$100),,(G35/$E$100)) -> 0 | L35: =IF(ISERROR(H35/$E$100),,(H35/$E$100)) -> 0
C36: 택시 | E36: =SUM(F36:H36) -> 13600 | F36: =SUMIFS('2월'!$I:$I,'2월'!$D:$D,C36,'2월'!$C:$C,$F$2) -> 13600 | G36: =SUMIFS('2월'!$I:$I,'2월'!$D:$D,C36,'2월'!$C:$C,$G$2) -> 0 | H36: =SUMIFS('2월'!$I:$I,'2월'!$D:$D,C36,'2월'!$C:$C,$H$2) -> 0 | J36: =IF(ISERROR(F36/$E$100),,(F36/$E$100)) -> 0.0017799421 | K36: =IF(ISERROR(G36/$E$100),,(G36/$E$100)) -> 0 | L36: =IF(ISERROR(H36/$E$100),,(H36/$E$100)) -> 0
C37: 교통_기타 | D37: 기차/시외버스/유류/답례/따릉이 | E37: =SUM(F37:H37) -> 0 | F37: =SUMIFS('2월'!$I:$I,'2월'!$D:$D,C37,'2월'!$C:$C,$F$2) -> 0 | G37: =SUMIFS('2월'!$I:$I,'2월'!$D:$D,C37,'2월'!$C:$C,$G$2) -> 0 | H37: =SUMIFS('2월'!$I:$I,'2월'!$D:$D,C37,'2월'!$C:$C,$H$2) -> 0 | J37: =IF(ISERROR(F37/$E$100),,(F37/$E$100)) -> 0 | K37: =IF(ISERROR(G37/$E$100),,(G37/$E$100)) -> 0 | L37: =IF(ISERROR(H37/$E$100),,(H37/$E$100)) -> 0
J38: =IF(ISERROR(F38/$E$100),,(F38/$E$100)) -> 0 | K38: =IF(ISERROR(G38/$E$100),,(G38/$E$100)) -> 0 | L38: =IF(ISERROR(H38/$E$100),,(H38/$E$100)) -> 0
C39: 세금 | D39: 주민세 | E39: =SUM(F39:H39) -> 0 | F39: =SUMIFS('2월'!$I:$I,'2월'!$D:$D,C39,'2월'!$C:$C,$F$2) -> 0 | G39: =SUMIFS('2월'!$I:$I,'2월'!$D:$D,C39,'2월'!$C:$C,$G$2) -> 0 | H39: =SUMIFS('2월'!$I:$I,'2월'!$D:$D,C39,'2월'!$C:$C,$H$2) -> 0 | J39: =IF(ISERROR(F39/$E$100),,(F39/$E$100)) -> 0 | K39: =IF(ISERROR(G39/$E$100),,(G39/$E$100)) -> 0 | L39: =IF(ISERROR(H39/$E$100),,(H39/$E$100)) -> 0
J40: =IF(ISERROR(F40/$E$100),,(F40/$E$100)) -> 0 | K40: =IF(ISERROR(G40/$E$100),,(G40/$E$100)) -> 0 | L40: =IF(ISERROR(H40/$E$100),,(H40/$E$100)) -> 0
...

Sheet 2월
A1: 날짜 | B1: 구매처 | C1: 사용자 | D1: 소분류 | E1: 지출(합계) | F1: 내용 | G1: 단가 | H1: 개수 | I1: 지출(매수) | J1: 결재수단 | K1: 증빙 | M1: =SUM(E:E) -> -11146646 | N1: =+M1-'2월(집계)'!E100+'2월(집계)'!E9 -> 7500
A3: 46054 | B3: 우렁쌈밥 | C3: 공동 | D3: 배달 | E3: =SUM(I3:I3) -> 24900 | F3: 제육볶음+우렁쌈밥 | G3: 24900 | H3: 1 | I3: =G3*H3 -> 24900 | J3: 농협 | K3: 0 | P3: 전기
A4: 46055 | B4: 새마을금고 | C4: 공동 | D4: 회수 | E4: =SUM(I4:I4) -> -6000000 | F4: 만기 | G4: -6000000 | H4: 1 | I4: =G4*H4 -> -6000000 | J4: 현금 | P4: 가스 | Q4: 시공비
A5: 46055 | B5: 새마을금고 | C5: 공동 | D5: 이자 | E5: =I5 -> -178155 | F5: 0.035 | G5: =-6178155-G4 -> -178155 | H5: 1 | I5: =G5*H5 -> -178155 | J5: 현금 | P5: 수리
A6: 46055 | B6: 제주반했어 | C6: 공동 | D6: 선물 | E6: =SUM(I6:I6) -> 51500 | G6: 51500 | H6: 1 | I6: =G6*H6 -> 51500 | J6: 현대
A7: 46055 | B7: 써브웨이 | C7: 아기 | D7: 외식_아침 | E7: =SUM(I7:I7) -> 7800 | F7: 로티세리 바비큐 치킨15 | G7: 7800 | H7: 1 | I7: =G7*H7 -> 7800 | J7: 삼성 | K7: 0 | P7: 관리_기타 | Q7: 예치금 | U7: 45870
A8: 46055 | B8: 화육면 | C8: 엉아 | D8: 외식_점심 | E8: =SUM(I8:I9) -> 19000 | F8: 고기국수 EYH | G8: 15000 | H8: 1 | I8: =G8*H8 -> 15000 | J8: 현대 | U8: 45871
A9: 46055 | B9: 화육면 | C9: 엉아 | D9: 차감 | G9: =19000-G8 -> 4000 | H9: 1 | I9: =G9*H9 -> 4000 | J9: 현대 | P9: 대출상환 | U9: 45872
A10: 46055 | B10: 가비당 | C10: 엉아 | D10: 배달 | E10: =SUM(I10:I10) -> 12300 | F10: 3일점심 초코가나슈쿠키 뽀또크림치즈쿠키 르뱅쿠키 | G10: 12300 | H10: 1 | I10: =G10*H10 -> 12300 | J10: 농협 | K10: 0 | P10: 대출이자 | U10: 45873
A11: 46055 | B11: LH | C11: 공동 | D11: 임차 | E11: =SUM(I11:I11) -> 311930 | F11: LH202601 | G11: 311930 | H11: 1 | I11: =G11*H11 -> 311930 | J11: 현금엉아 | P11: 저축 | U11: 45874
A12: 46056 | B12: 제주반했어 | C12: 공동 | D12: 선물 | E12: =SUM(I12:I12) -> 52500 | F12: 첫째날은 광고쿠폰 받아서 1000원 더 싼거 | G12: 52500 | H12: 1 | I12: =G12*H12 -> 52500 | J12: 현대 | P12: 이자 | U12: 45875
A13: 46056 | B13: 써브웨이 | C13: 아기 | D13: 외식_아침 | E13: =SUM(I13:I13) -> 7600 | F13: 풀드포크 바비큐15 | G13: 7600 | H13: 1 | I13: =G13*H13 -> 7600 | J13: 삼성 | K13: 0 | P13: 적금 | U13: 45876
A14: 46056 | B14: 서울재활의학과 | C14: 아기 | D14: 병원 | E14: =SUM(I14:I14) -> 100900 | G14: 100900 | H14: 1 | I14: =G14*H14 -> 100900 | J14: 농협 | K14: 0 | P14: 보험 | U14: 45877
A15: 46056 | B15: 비즈엘약국 | C15: 아기 | D15: 약 | E15: =SUM(I15:I15) -> 4100 | F15: 조제의약품 | G15: 4100 | H15: 1 | I15: =G15*H15 -> 4100 | J15: 농협 | K15: 0 | P15: 통신 | U15: 45878
A16: 46056 | B16: 크레이지카츠 | C16: 아기 | D16: 외식_저녁 | E16: =SUM(I16:I16) -> 1000 | F16: 선불13 | G16: 1000 | H16: 1 | I16: =G16*H16 -> 1000 | J16: 농협 | K16: 0 | U16: 45879
A17: 46056 | B17: 이마트 | C17: 공동 | D17: 음주 | E17: =SUM(I17:I18) -> 26600 | F17: 미스터보스턴 진 750 | G17: 8800 | H17: 1 | I17: =G17*H17 -> 8800 | J17: 국민 | K17: 0 | P17: 전화 | U17: 45880
A18: 46056 | B18: 이마트 | C18: 공동 | D18: 음주 | F18: 1887 프리미티보 | G18: 17800 | H18: 1 | I18: =G18*H18 -> 17800 | J18: 국민 | K18: 0 | P18: 인터넷 | U18: 45881
A19: 46057 | B19: 써브웨이 | C19: 아기 | D19: 외식_아침 | E19: =SUM(I19:I19) -> 7400 | F19: 참치15 에그슬라이스 | G19: 7400 | H19: 1 | I19: =G19*H19 -> 7400 | J19: 삼성 | K19: 0 | P19: 교통 | U19: 45882
A20: 46057 | B20: 고덕방 | C20: 아기 | D20: 커피 | E20: =SUM(I20:I20) -> 3400 | F20: 아이스아메리카노 | G20: 3400 | H20: 1 | I20: =G20*H20 -> 3400 | J20: 삼성 | K20: 0 | P20: 택시 | U20: 45883
A21: 46057 | B21: 실속보쌈 | C21: 엉아 | D21: 배달 | E21: =SUM(I21:I21) -> 12900 | F21: 1인보쌈도시락 | G21: 12900 | H21: 1 | I21: =G21*H21 -> 12900 | J21: 농협 | K21: 0 | P21: 교통_기타 | Q21: 기차/시외버스/유류/답례/따릉이 | U21: 45884
A22: 46057 | B22: 피자알볼로 | C22: 엉아 | D22: 배달 | E22: =SUM(I22:I22) -> 15000 | F22: 단호박피자 | G22: 15000 | H22: 1 | I22: =G22*H22 -> 15000 | J22: 농협 | K22: 0 | P22: 세금 | Q22: 주민세 | U22: 45885
A23: 46057 | B23: 서울재활의학과 | C23: 아기 | D23: 병원 | E23: =SUM(I23:I23) -> 14600 | G23: 14600 | H23: 1 | I23: =G23*H23 -> 14600 | J23: 삼성 | K23: 0 | P23: 수수료 | Q23: 주민센터/은행/보증료(매2년) | U23: 45886
A24: 46057 | C24: 아기 | D24: 외식_저녁 | E24: =SUM(I24:I24) -> 14900 | F24: 저녁, 뭐먹었는지 모르겠음 | G24: 14900 | H24: 1 | I24: =G24*H24 -> 14900 | J24: 국민 | M24: ?? | P24: 식비 | U24: 45887
A25: 46057 | B25: 코스트코 | C25: 공동 | D25: 음주 | E25: =SUM(I25:I25) -> 23290 | F25: 삐즙 | G25: 23290 | H25: 1 | I25: =G25*H25 -> 23290 | J25: 현대 | M25: ?? | P25: 외식_아침 | U25: 45888
A26: 46058 | B26: 써브웨이 | C26: 아기 | D26: 외식_아침 | E26: =SUM(I26:I26) -> 6800 | F26: 로티세리 바비큐 치킨15 | G26: 6800 | H26: 1 | I26: =G26*H26 -> 6800 | J26: 국민 | K26: 0 | P26: 외식_점심 | U26: 45889
A27: 46058 | B27: 더벤티 | C27: 아기 | D27: 커피 | E27: =SUM(I27:I27) -> 2000 | G27: 2000 | H27: 1 | I27: =G27*H27 -> 2000 | J27: 국민 | P27: 외식_저녁 | U27: 45890
A28: 46058 | B28: 가비당 | C28: 엉아 | D28: 배달 | E28: =SUM(I28:I28) -> 28800 | F28: 두끼인듯 두끼 바스크치즈케이크 초코휘낭시에 르뱅쿠키 초코가나슈쿠키 초코스모어쿠키 솔트카라멜휘낭시에 | G28: 28800 | H28: 1 | I28: =G28*H28 -> 28800 | J28: 농협 | K28: 0 | P28: 배달 | U28: 45891
A29: 46059 | B29: 고덕방 | C29: 아기 | D29: 커피 | E29: =SUM(I29:I29) -> 3400 | F29: 아이스아메리카노 | G29: 3400 | H29: 1 | I29: =G29*H29 -> 3400 | J29: 삼성 | K29: 0 | P29: 음주 | U29: 45892
A30: 46059 | B30: 한화손보 | C30: 아기 | D30: 보험 | E30: =SUM(I30:I30) -> -196700 | G30: -196700 | H30: 1 | I30: =G30*H30 -> -196700 | J30: 국민 | U30: 45893
A31: 46059 | B31: 서울재활의학과 | C31: 아기 | D31: 병원 | E31: =SUM(I31:I31) -> 14600 | G31: 14600 | H31: 1 | I31: =G31*H31 -> 14600 | J31: 삼성 | K31: 0 | P31: 커피 | U31: 45894
A32: 46059 | B32: 비즈엘약국 | C32: 아기 | D32: 약 | E32: =SUM(I32:I32) -> 3100 | G32: 3100 | H32: 1 | I32: =G32*H32 -> 3100 | J32: 삼성 | P32: 생수 | Q32: 생수/정수기 | U32: 45895
A33: 46059 | B33: 교촌치킨 | C33: 공동 | D33: 배달 | E33: =SUM(I33:I33) -> 26000 | F33: 한마리 간장허니갈릭반반 치즈트러플시즈님 | G33: 26000 | H33: 1 | I33: =G33*H33 -> 26000 | J33: 농협 | K33: 0 | P33: 간식 | U33: 45896
A34: 46059 | B34: CU | C34: 공동 | D34: 음주 | E34: =SUM(I34:I34) -> 16800 | F34: 카스1.6 켈리1.6 바삭팝콘스팸맛 | G34: 16800 | H34: 1 | I34: =G34*H34 -> 16800 | J34: 현금아기 | K34: 0 | P34: 식자재 | U34: 45897
A35: 46060 | B35: 인생맛죽 | C35: 엉아 | D35: 배달 | E35: =SUM(I35:I35) -> 11300 | F35: 보양삼계죽 계란찜 | G35: 11300 | H35: 1 | I35: =G35*H35 -> 11300 | J35: 국민 | K35: 0 | P35: 과일 | U35: 45898
A36: 46060 | B36: 모어댄구디스 | C36: 엉아 | D36: 배달 | E36: =SUM(I36:I36) -> 11100 | F36: 이거 커피 만원침? 아니면 점심? 딸기생크림도넛 초콜릿도넛 라뗴 | G36: 11100 | H36: 1 | I36: =G36*H36 -> 11100 | J36: 국민 | K36: 0 | P36: 배달비 | Q36: 배달음식 | U36: 45899
A37: 46060 | B37: 생생직판장 | C37: 아기 | D37: 배달 | E37: =SUM(I37:I37) -> 30000 | F37: 34000 두끼 숭어+참돔 | G37: 30000 | H37: 1 | I37: =G37*H37 -> 30000 | J37: 국민 | K37: 0 | P37: 주거 | U37: 45900
A38: 46060 | B38: 인생맛죽 | C38: 엉아 | D38: 배달 | E38: =SUM(I38:I38) -> 12800 | F38: 고소한참치죽 메추리알조림 | G38: 12800 | H38: 1 | I38: =G38*H38 -> 12800 | J38: 국민 | K38: 0 | P38: 주방 | Q38: 세제/수세미/조리도구
A39: 46061 | B39: Lagoon74 | C39: 공동 | D39: 배달 | E39: =SUM(I39:I39) -> 37000 | F39: 비싼거먹기로함 두끼 화덕마리게리따피자 빼쉐파스타 | G39: 37000 | H39: 1 | I39: =G39*H39 -> 37000 | J39: 국민 | K39: 0 | P39: 욕실 | Q39: 두루마리화장지/수건/샤워볼
A40: 46061 | B40: 원할머니보쌈 | C40: 공동 | D40: 배달 | E40: =SUM(I40:I40) -> 21000 | G40: 21000 | H40: 1 | I40: =G40*H40 -> 21000 | J40: 국민 | P40: 가전 | Q40: 렌탈/수리
A41: 46061 | B41: PNT몰 | C41: 아기 | D41: 영양 | E41: =SUM(I41:I41) -> 71000 | F41: 유산균 2달치 | G41: 71000 | H41: 1 | I41: =G41*H41 -> 71000 | J41: 현금아기 | P41: 가구 | Q41: 커튼/옷걸이/이불
...
